2013-07-28 18:10:08,931 [ERROR 5767] Failure trying to retrieve table definition for table prueba2.exts.  Please fix RD.
Traceback (most recent call last):
  File "/usr/local/lib/python2.7/dist-packages/gavodachs-0.8.7-py2.7.egg/gavo/svcs/service.py", line 522, in getTableSet
    tables.append(mth.getTableDefForTable(row["tableName"]))
  File "/usr/local/lib/python2.7/dist-packages/gavodachs-0.8.7-py2.7.egg/gavo/rsc/metatable.py", line 119, in getTableDefForTable
    return base.caches.getRD(tableRec["sourceRD"]
  File "/usr/local/lib/python2.7/dist-packages/gavodachs-0.8.7-py2.7.egg/gavo/rscdesc.py", line 603, in getRDCached
    return _loadRDIntoCache(srcId, rdCache)
  File "/usr/local/lib/python2.7/dist-packages/gavodachs-0.8.7-py2.7.egg/gavo/rscdesc.py", line 556, in _loadRDIntoCache
    cacheDict[canonicalRDId] = getRD(canonicalRDId, useRD=rd)
  File "/usr/local/lib/python2.7/dist-packages/gavodachs-0.8.7-py2.7.egg/gavo/rscdesc.py", line 471, in getRD
    srcPath, inputFile = getRDInputStream(rd.sourceId)
  File "/usr/local/lib/python2.7/dist-packages/gavodachs-0.8.7-py2.7.egg/gavo/rscdesc.py", line 403, in getRDInputStream
    raise base.RDNotFound(srcId)
RDNotFound: resource descriptor u'prueba2/q' could not be located in file system
2013-08-08 12:25:46,890 [ERROR 4196] While executing TAP job WuBuxK: Could not parse your query: Expected "SELECT" (at char 0), (line:1, col:1)
Traceback (most recent call last):
  File "/usr/local/lib/python2.7/dist-packages/gavodachs-0.8.7-py2.7.egg/gavo/protocols/taprunner.py", line 282, in runTAPJob
    runTAPJobNoState(parameters, jobId, queryProfile, timeout)
  File "/usr/local/lib/python2.7/dist-packages/gavodachs-0.8.7-py2.7.egg/gavo/protocols/taprunner.py", line 256, in runTAPJobNoState
    parameters, jobId, queryProfile, timeout))
  File "/usr/local/lib/python2.7/dist-packages/gavodachs-0.8.7-py2.7.egg/gavo/protocols/taprunner.py", line 240, in getQTableFromJob
    tdsForUploads, maxrec)
  File "/usr/local/lib/python2.7/dist-packages/gavodachs-0.8.7-py2.7.egg/gavo/protocols/taprunner.py", line 153, in runTAPQuery
    adqlglue.mapADQLErrors(*sys.exc_info())
  File "/usr/local/lib/python2.7/dist-packages/gavodachs-0.8.7-py2.7.egg/gavo/protocols/adqlglue.py", line 298, in mapADQLErrors
    unicode(excValue), "query"))
ValidationError: Could not parse your query: Expected "SELECT" (at char 0), (line:1, col:1)
2013-08-08 12:25:46,945 [ERROR 4196] Could not parse your query: Expected "SELECT" (at char 0), (line:1, col:1) (see info for traceback)
None
2013-08-08 12:26:12,003 [ERROR 4196] While executing TAP job eeugWG: Could not parse your query: Expected "SELECT" (at char 0), (line:1, col:1)
Traceback (most recent call last):
  File "/usr/local/lib/python2.7/dist-packages/gavodachs-0.8.7-py2.7.egg/gavo/protocols/taprunner.py", line 282, in runTAPJob
    runTAPJobNoState(parameters, jobId, queryProfile, timeout)
  File "/usr/local/lib/python2.7/dist-packages/gavodachs-0.8.7-py2.7.egg/gavo/protocols/taprunner.py", line 256, in runTAPJobNoState
    parameters, jobId, queryProfile, timeout))
  File "/usr/local/lib/python2.7/dist-packages/gavodachs-0.8.7-py2.7.egg/gavo/protocols/taprunner.py", line 240, in getQTableFromJob
    tdsForUploads, maxrec)
  File "/usr/local/lib/python2.7/dist-packages/gavodachs-0.8.7-py2.7.egg/gavo/protocols/taprunner.py", line 153, in runTAPQuery
    adqlglue.mapADQLErrors(*sys.exc_info())
  File "/usr/local/lib/python2.7/dist-packages/gavodachs-0.8.7-py2.7.egg/gavo/protocols/adqlglue.py", line 298, in mapADQLErrors
    unicode(excValue), "query"))
ValidationError: Could not parse your query: Expected "SELECT" (at char 0), (line:1, col:1)
2013-08-08 12:26:12,026 [ERROR 4196] Could not parse your query: Expected "SELECT" (at char 0), (line:1, col:1) (see info for traceback)
None
2013-08-08 12:28:01,506 [ERROR 4196] While executing TAP job L5vZcz: No such field known: column 'ramin' could not be located in table metadata
Traceback (most recent call last):
  File "/usr/local/lib/python2.7/dist-packages/gavodachs-0.8.7-py2.7.egg/gavo/protocols/taprunner.py", line 282, in runTAPJob
    runTAPJobNoState(parameters, jobId, queryProfile, timeout)
  File "/usr/local/lib/python2.7/dist-packages/gavodachs-0.8.7-py2.7.egg/gavo/protocols/taprunner.py", line 256, in runTAPJobNoState
    parameters, jobId, queryProfile, timeout))
  File "/usr/local/lib/python2.7/dist-packages/gavodachs-0.8.7-py2.7.egg/gavo/protocols/taprunner.py", line 240, in getQTableFromJob
    tdsForUploads, maxrec)
  File "/usr/local/lib/python2.7/dist-packages/gavodachs-0.8.7-py2.7.egg/gavo/protocols/taprunner.py", line 153, in runTAPQuery
    adqlglue.mapADQLErrors(*sys.exc_info())
  File "/usr/local/lib/python2.7/dist-packages/gavodachs-0.8.7-py2.7.egg/gavo/protocols/adqlglue.py", line 301, in mapADQLErrors
    unicode(excValue), "query"))
ValidationError: No such field known: column 'ramin' could not be located in table metadata
2013-08-08 12:28:01,526 [ERROR 4196] No such field known: column 'ramin' could not be located in table metadata (see info for traceback)
None
2013-08-08 12:28:48,576 [ERROR 4196] While executing TAP job 3D_zhh: No such field known: column 'ra' could not be located in table metadata
Traceback (most recent call last):
  File "/usr/local/lib/python2.7/dist-packages/gavodachs-0.8.7-py2.7.egg/gavo/protocols/taprunner.py", line 282, in runTAPJob
    runTAPJobNoState(parameters, jobId, queryProfile, timeout)
  File "/usr/local/lib/python2.7/dist-packages/gavodachs-0.8.7-py2.7.egg/gavo/protocols/taprunner.py", line 256, in runTAPJobNoState
    parameters, jobId, queryProfile, timeout))
  File "/usr/local/lib/python2.7/dist-packages/gavodachs-0.8.7-py2.7.egg/gavo/protocols/taprunner.py", line 240, in getQTableFromJob
    tdsForUploads, maxrec)
  File "/usr/local/lib/python2.7/dist-packages/gavodachs-0.8.7-py2.7.egg/gavo/protocols/taprunner.py", line 153, in runTAPQuery
    adqlglue.mapADQLErrors(*sys.exc_info())
  File "/usr/local/lib/python2.7/dist-packages/gavodachs-0.8.7-py2.7.egg/gavo/protocols/adqlglue.py", line 301, in mapADQLErrors
    unicode(excValue), "query"))
ValidationError: No such field known: column 'ra' could not be located in table metadata
2013-08-08 12:28:48,598 [ERROR 4196] No such field known: column 'ra' could not be located in table metadata (see info for traceback)
None
2013-08-08 12:29:00,989 [ERROR 4196] While executing TAP job WT0mbj: invalid input syntax for type numeric: "RA"
LINE 1: ...HOUT HOLD FOR SELECT * FROM lmcextinct.exts WHERE 'RA' = 78....
                                                             ^
Traceback (most recent call last):
  File "/usr/local/lib/python2.7/dist-packages/gavodachs-0.8.7-py2.7.egg/gavo/protocols/taprunner.py", line 282, in runTAPJob
    runTAPJobNoState(parameters, jobId, queryProfile, timeout)
  File "/usr/local/lib/python2.7/dist-packages/gavodachs-0.8.7-py2.7.egg/gavo/protocols/taprunner.py", line 267, in runTAPJobNoState
    svcs.mapDBErrors(*sys.exc_info())
  File "/usr/local/lib/python2.7/dist-packages/gavodachs-0.8.7-py2.7.egg/gavo/svcs/standardcores.py", line 314, in mapDBErrors
    raise base.ui.logOldExc(base.ValidationError(unicode(excValue), "query"))
ValidationError: invalid input syntax for type numeric: "RA"
LINE 1: ...HOUT HOLD FOR SELECT * FROM lmcextinct.exts WHERE 'RA' = 78....
                                                             ^

2013-08-08 12:29:01,033 [ERROR 4196] invalid input syntax for type numeric: "RA"
LINE 1: ...HOUT HOLD FOR SELECT * FROM lmcextinct.exts WHERE 'RA' = 78....
                                                             ^
 (see info for traceback)
None
2013-08-08 12:59:26,099 [ERROR 4196] While executing TAP job FbobIo: Could not locate Table 'lmcextinct.exts'
Traceback (most recent call last):
  File "/usr/local/lib/python2.7/dist-packages/gavodachs-0.8.7-py2.7.egg/gavo/protocols/taprunner.py", line 282, in runTAPJob
    runTAPJobNoState(parameters, jobId, queryProfile, timeout)
  File "/usr/local/lib/python2.7/dist-packages/gavodachs-0.8.7-py2.7.egg/gavo/protocols/taprunner.py", line 256, in runTAPJobNoState
    parameters, jobId, queryProfile, timeout))
  File "/usr/local/lib/python2.7/dist-packages/gavodachs-0.8.7-py2.7.egg/gavo/protocols/taprunner.py", line 240, in getQTableFromJob
    tdsForUploads, maxrec)
  File "/usr/local/lib/python2.7/dist-packages/gavodachs-0.8.7-py2.7.egg/gavo/protocols/taprunner.py", line 153, in runTAPQuery
    adqlglue.mapADQLErrors(*sys.exc_info())
  File "/usr/local/lib/python2.7/dist-packages/gavodachs-0.8.7-py2.7.egg/gavo/protocols/adqlglue.py", line 306, in mapADQLErrors
    svcs.mapDBErrors(excType, excValue, excTb)
  File "/usr/local/lib/python2.7/dist-packages/gavodachs-0.8.7-py2.7.egg/gavo/svcs/standardcores.py", line 312, in mapDBErrors
    excValue.what, excValue.lookedFor), "query"))
ValidationError: Could not locate Table 'lmcextinct.exts'
2013-08-08 12:59:26,120 [ERROR 4196] Could not locate Table 'lmcextinct.exts' (see info for traceback)
None
2013-08-08 12:59:47,623 [ERROR 4196] While executing TAP job pUqBA_: Could not locate Table 'lmcextinct.exts'
Traceback (most recent call last):
  File "/usr/local/lib/python2.7/dist-packages/gavodachs-0.8.7-py2.7.egg/gavo/protocols/taprunner.py", line 282, in runTAPJob
    runTAPJobNoState(parameters, jobId, queryProfile, timeout)
  File "/usr/local/lib/python2.7/dist-packages/gavodachs-0.8.7-py2.7.egg/gavo/protocols/taprunner.py", line 256, in runTAPJobNoState
    parameters, jobId, queryProfile, timeout))
  File "/usr/local/lib/python2.7/dist-packages/gavodachs-0.8.7-py2.7.egg/gavo/protocols/taprunner.py", line 240, in getQTableFromJob
    tdsForUploads, maxrec)
  File "/usr/local/lib/python2.7/dist-packages/gavodachs-0.8.7-py2.7.egg/gavo/protocols/taprunner.py", line 153, in runTAPQuery
    adqlglue.mapADQLErrors(*sys.exc_info())
  File "/usr/local/lib/python2.7/dist-packages/gavodachs-0.8.7-py2.7.egg/gavo/protocols/adqlglue.py", line 306, in mapADQLErrors
    svcs.mapDBErrors(excType, excValue, excTb)
  File "/usr/local/lib/python2.7/dist-packages/gavodachs-0.8.7-py2.7.egg/gavo/svcs/standardcores.py", line 312, in mapDBErrors
    excValue.what, excValue.lookedFor), "query"))
ValidationError: Could not locate Table 'lmcextinct.exts'
2013-08-08 12:59:47,655 [ERROR 4196] Could not locate Table 'lmcextinct.exts' (see info for traceback)
None
2013-08-11 15:23:08,966 [ERROR 5283] RD lmcextinct/q#exts faulty, ignored.
Traceback (most recent call last):
  File "/usr/local/lib/python2.7/dist-packages/gavodachs-0.8.7-py2.7.egg/gavo/registry/publication.py", line 299, in getRDs
    allRDs.append(base.caches.getRD(rdPath, doQueries=False))
  File "/usr/local/lib/python2.7/dist-packages/gavodachs-0.8.7-py2.7.egg/gavo/rscdesc.py", line 589, in getRDCached
    return getRD(srcId, **kwargs)
  File "/usr/local/lib/python2.7/dist-packages/gavodachs-0.8.7-py2.7.egg/gavo/rscdesc.py", line 471, in getRD
    srcPath, inputFile = getRDInputStream(rd.sourceId)
  File "/usr/local/lib/python2.7/dist-packages/gavodachs-0.8.7-py2.7.egg/gavo/rscdesc.py", line 403, in getRDInputStream
    raise base.RDNotFound(srcId)
RDNotFound: resource descriptor 'lmcextinct/q#exts' could not be located in file system
2013-08-11 16:11:55,040 [ERROR 5896] Error during UWS execution of job o0VL08
Traceback (most recent call last):
  File "/usr/local/lib/python2.7/dist-packages/gavodachs-0.8.7-py2.7.egg/gavo/protocols/taprunner.py", line 282, in runTAPJob
    runTAPJobNoState(parameters, jobId, queryProfile, timeout)
  File "/usr/local/lib/python2.7/dist-packages/gavodachs-0.8.7-py2.7.egg/gavo/protocols/taprunner.py", line 256, in runTAPJobNoState
    parameters, jobId, queryProfile, timeout))
  File "/usr/local/lib/python2.7/dist-packages/gavodachs-0.8.7-py2.7.egg/gavo/protocols/taprunner.py", line 240, in getQTableFromJob
    tdsForUploads, maxrec)
  File "/usr/local/lib/python2.7/dist-packages/gavodachs-0.8.7-py2.7.egg/gavo/protocols/taprunner.py", line 153, in runTAPQuery
    adqlglue.mapADQLErrors(*sys.exc_info())
  File "/usr/local/lib/python2.7/dist-packages/gavodachs-0.8.7-py2.7.egg/gavo/protocols/adqlglue.py", line 306, in mapADQLErrors
    svcs.mapDBErrors(excType, excValue, excTb)
  File "/usr/local/lib/python2.7/dist-packages/gavodachs-0.8.7-py2.7.egg/gavo/protocols/taprunner.py", line 144, in runTAPQuery
    tdsForUploads=tdsForUploads, externalLimit=maxrec)
  File "/usr/local/lib/python2.7/dist-packages/gavodachs-0.8.7-py2.7.egg/gavo/protocols/adqlglue.py", line 242, in morphADQL
    getFieldInfoGetter(metaProfile, tdsForUploads))
  File "/usr/local/lib/python2.7/dist-packages/gavodachs-0.8.7-py2.7.egg/gavo/adql/__init__.py", line 50, in parseAnnotating
    ctx = annotate(parsedTree, fieldInfoGetter)
  File "/usr/local/lib/python2.7/dist-packages/gavodachs-0.8.7-py2.7.egg/gavo/adql/annotations.py", line 99, in annotate
    _annotateTraverse(node, context)
  File "/usr/local/lib/python2.7/dist-packages/gavodachs-0.8.7-py2.7.egg/gavo/adql/annotations.py", line 79, in _annotateTraverse
    _annotateTraverse(c, context)
  File "/usr/local/lib/python2.7/dist-packages/gavodachs-0.8.7-py2.7.egg/gavo/adql/annotations.py", line 79, in _annotateTraverse
    _annotateTraverse(c, context)
  File "/usr/local/lib/python2.7/dist-packages/gavodachs-0.8.7-py2.7.egg/gavo/adql/annotations.py", line 82, in _annotateTraverse
    node.addFieldInfos(context)
  File "/usr/local/lib/python2.7/dist-packages/gavodachs-0.8.7-py2.7.egg/gavo/adql/nodes.py", line 460, in addFieldInfos
    self.fieldInfos = fieldinfos.TableFieldInfos.makeForNode(self, context)
  File "/usr/local/lib/python2.7/dist-packages/gavodachs-0.8.7-py2.7.egg/gavo/adql/fieldinfos.py", line 129, in makeForNode
    tableNode.originalTable):
  File "/usr/local/lib/python2.7/dist-packages/gavodachs-0.8.7-py2.7.egg/gavo/utils/codetricks.py", line 578, in fun
    cache[args] = origFun(*args)
  File "/usr/local/lib/python2.7/dist-packages/gavodachs-0.8.7-py2.7.egg/gavo/protocols/adqlglue.py", line 183, in getFieldInfos
    td = mth.getTableDefForTable(adql.flatten(tableName))
  File "/usr/local/lib/python2.7/dist-packages/gavodachs-0.8.7-py2.7.egg/gavo/rsc/metatable.py", line 119, in getTableDefForTable
    return base.caches.getRD(tableRec["sourceRD"]
  File "/usr/local/lib/python2.7/dist-packages/gavodachs-0.8.7-py2.7.egg/gavo/rscdesc.py", line 603, in getRDCached
    return _loadRDIntoCache(srcId, rdCache)
  File "/usr/local/lib/python2.7/dist-packages/gavodachs-0.8.7-py2.7.egg/gavo/rscdesc.py", line 556, in _loadRDIntoCache
    cacheDict[canonicalRDId] = getRD(canonicalRDId, useRD=rd)
  File "/usr/local/lib/python2.7/dist-packages/gavodachs-0.8.7-py2.7.egg/gavo/rscdesc.py", line 481, in getRD
    rd = base.parseFromStream(rd, inputFile, context=context)
  File "/usr/local/lib/python2.7/dist-packages/gavodachs-0.8.7-py2.7.egg/gavo/base/xmlstruct.py", line 197, in parseFromStream
    res = feedTo(rootStruct, eventSource, context)
  File "/usr/local/lib/python2.7/dist-packages/gavodachs-0.8.7-py2.7.egg/gavo/base/xmlstruct.py", line 170, in feedTo
    evProc.feed(type, name, payload)
  File "/usr/local/lib/python2.7/dist-packages/gavodachs-0.8.7-py2.7.egg/gavo/base/xmlstruct.py", line 88, in feed
    self._feedToStructured(type, name, value)
  File "/usr/local/lib/python2.7/dist-packages/gavodachs-0.8.7-py2.7.egg/gavo/base/xmlstruct.py", line 64, in _feedToStructured
    next = self.curParser.feedEvent(self.ctx, type, name, value)
  File "/usr/local/lib/python2.7/dist-packages/gavodachs-0.8.7-py2.7.egg/gavo/base/common.py", line 60, in feedEvent
    return self.start_(ctx, name, value)
  File "/usr/local/lib/python2.7/dist-packages/gavodachs-0.8.7-py2.7.egg/gavo/base/structure.py", line 305, in start_
    attDef = self.getAttribute(name)
  File "/usr/local/lib/python2.7/dist-packages/gavodachs-0.8.7-py2.7.egg/gavo/base/structure.py", line 276, in getAttribute
    "%s elements have no %s attributes or children."%(self.name_, name))
StructureError: At /data/gavo/inputs/lmcextinct/q.rd, (58, 1): resource elements have no publish attributes or children.
2013-08-11 16:11:55,126 [ERROR 5896] While executing TAP job o0VL08: At /data/gavo/inputs/lmcextinct/q.rd, (58, 1): resource elements have no publish attributes or children.
Traceback (most recent call last):
  File "/usr/local/lib/python2.7/dist-packages/gavodachs-0.8.7-py2.7.egg/gavo/protocols/taprunner.py", line 282, in runTAPJob
    runTAPJobNoState(parameters, jobId, queryProfile, timeout)
  File "/usr/local/lib/python2.7/dist-packages/gavodachs-0.8.7-py2.7.egg/gavo/protocols/taprunner.py", line 256, in runTAPJobNoState
    parameters, jobId, queryProfile, timeout))
  File "/usr/local/lib/python2.7/dist-packages/gavodachs-0.8.7-py2.7.egg/gavo/protocols/taprunner.py", line 240, in getQTableFromJob
    tdsForUploads, maxrec)
  File "/usr/local/lib/python2.7/dist-packages/gavodachs-0.8.7-py2.7.egg/gavo/protocols/taprunner.py", line 153, in runTAPQuery
    adqlglue.mapADQLErrors(*sys.exc_info())
  File "/usr/local/lib/python2.7/dist-packages/gavodachs-0.8.7-py2.7.egg/gavo/protocols/adqlglue.py", line 306, in mapADQLErrors
    svcs.mapDBErrors(excType, excValue, excTb)
  File "/usr/local/lib/python2.7/dist-packages/gavodachs-0.8.7-py2.7.egg/gavo/protocols/taprunner.py", line 144, in runTAPQuery
    tdsForUploads=tdsForUploads, externalLimit=maxrec)
  File "/usr/local/lib/python2.7/dist-packages/gavodachs-0.8.7-py2.7.egg/gavo/protocols/adqlglue.py", line 242, in morphADQL
    getFieldInfoGetter(metaProfile, tdsForUploads))
  File "/usr/local/lib/python2.7/dist-packages/gavodachs-0.8.7-py2.7.egg/gavo/adql/__init__.py", line 50, in parseAnnotating
    ctx = annotate(parsedTree, fieldInfoGetter)
  File "/usr/local/lib/python2.7/dist-packages/gavodachs-0.8.7-py2.7.egg/gavo/adql/annotations.py", line 99, in annotate
    _annotateTraverse(node, context)
  File "/usr/local/lib/python2.7/dist-packages/gavodachs-0.8.7-py2.7.egg/gavo/adql/annotations.py", line 79, in _annotateTraverse
    _annotateTraverse(c, context)
  File "/usr/local/lib/python2.7/dist-packages/gavodachs-0.8.7-py2.7.egg/gavo/adql/annotations.py", line 79, in _annotateTraverse
    _annotateTraverse(c, context)
  File "/usr/local/lib/python2.7/dist-packages/gavodachs-0.8.7-py2.7.egg/gavo/adql/annotations.py", line 82, in _annotateTraverse
    node.addFieldInfos(context)
  File "/usr/local/lib/python2.7/dist-packages/gavodachs-0.8.7-py2.7.egg/gavo/adql/nodes.py", line 460, in addFieldInfos
    self.fieldInfos = fieldinfos.TableFieldInfos.makeForNode(self, context)
  File "/usr/local/lib/python2.7/dist-packages/gavodachs-0.8.7-py2.7.egg/gavo/adql/fieldinfos.py", line 129, in makeForNode
    tableNode.originalTable):
  File "/usr/local/lib/python2.7/dist-packages/gavodachs-0.8.7-py2.7.egg/gavo/utils/codetricks.py", line 578, in fun
    cache[args] = origFun(*args)
  File "/usr/local/lib/python2.7/dist-packages/gavodachs-0.8.7-py2.7.egg/gavo/protocols/adqlglue.py", line 183, in getFieldInfos
    td = mth.getTableDefForTable(adql.flatten(tableName))
  File "/usr/local/lib/python2.7/dist-packages/gavodachs-0.8.7-py2.7.egg/gavo/rsc/metatable.py", line 119, in getTableDefForTable
    return base.caches.getRD(tableRec["sourceRD"]
  File "/usr/local/lib/python2.7/dist-packages/gavodachs-0.8.7-py2.7.egg/gavo/rscdesc.py", line 603, in getRDCached
    return _loadRDIntoCache(srcId, rdCache)
  File "/usr/local/lib/python2.7/dist-packages/gavodachs-0.8.7-py2.7.egg/gavo/rscdesc.py", line 556, in _loadRDIntoCache
    cacheDict[canonicalRDId] = getRD(canonicalRDId, useRD=rd)
  File "/usr/local/lib/python2.7/dist-packages/gavodachs-0.8.7-py2.7.egg/gavo/rscdesc.py", line 481, in getRD
    rd = base.parseFromStream(rd, inputFile, context=context)
  File "/usr/local/lib/python2.7/dist-packages/gavodachs-0.8.7-py2.7.egg/gavo/base/xmlstruct.py", line 197, in parseFromStream
    res = feedTo(rootStruct, eventSource, context)
  File "/usr/local/lib/python2.7/dist-packages/gavodachs-0.8.7-py2.7.egg/gavo/base/xmlstruct.py", line 170, in feedTo
    evProc.feed(type, name, payload)
  File "/usr/local/lib/python2.7/dist-packages/gavodachs-0.8.7-py2.7.egg/gavo/base/xmlstruct.py", line 88, in feed
    self._feedToStructured(type, name, value)
  File "/usr/local/lib/python2.7/dist-packages/gavodachs-0.8.7-py2.7.egg/gavo/base/xmlstruct.py", line 64, in _feedToStructured
    next = self.curParser.feedEvent(self.ctx, type, name, value)
  File "/usr/local/lib/python2.7/dist-packages/gavodachs-0.8.7-py2.7.egg/gavo/base/common.py", line 60, in feedEvent
    return self.start_(ctx, name, value)
  File "/usr/local/lib/python2.7/dist-packages/gavodachs-0.8.7-py2.7.egg/gavo/base/structure.py", line 305, in start_
    attDef = self.getAttribute(name)
  File "/usr/local/lib/python2.7/dist-packages/gavodachs-0.8.7-py2.7.egg/gavo/base/structure.py", line 276, in getAttribute
    "%s elements have no %s attributes or children."%(self.name_, name))
StructureError: At /data/gavo/inputs/lmcextinct/q.rd, (58, 1): resource elements have no publish attributes or children.
2013-08-11 16:11:55,146 [ERROR 5896] At /data/gavo/inputs/lmcextinct/q.rd, (58, 1): resource elements have no publish attributes or children. (see info for traceback)
None
2014-05-11 11:56:42,836 [ERROR 24471] Uncaught exception at toplevel
Traceback (most recent call last):
  File "/usr/lib/python2.7/dist-packages/gavo/user/cli.py", line 158, in main
    funcToRun()
  File "/usr/lib/python2.7/dist-packages/gavo/user/serve.py", line 323, in main
    args.subAction(args)
  File "/usr/lib/python2.7/dist-packages/gavo/user/serve.py", line 244, in start
    open(os.path.join(base.getConfig("logDir"), "server.stderr"), "a"),
IOError: [Errno 13] Permission denied: u'/home/gavo/LIRAE/LIRAE-DaCHS/logs/server.stderr'
2014-05-11 12:51:57,801 [ERROR 25894] Uncaught exception at toplevel
Traceback (most recent call last):
  File "/usr/lib/python2.7/dist-packages/gavo/user/cli.py", line 158, in main
    funcToRun()
  File "/usr/lib/python2.7/dist-packages/gavo/user/serve.py", line 323, in main
    args.subAction(args)
  File "/usr/lib/python2.7/dist-packages/gavo/user/serve.py", line 289, in restart
    start(args)
  File "/usr/lib/python2.7/dist-packages/gavo/user/serve.py", line 245, in start
    _startServer)
  File "/usr/lib/python2.7/dist-packages/gavo/user/serve.py", line 161, in daemonize
    callable()
  File "/usr/lib/python2.7/dist-packages/gavo/user/serve.py", line 224, in _startServer
    root.site.webLog = _configureTwistedLog()
  File "/usr/lib/python2.7/dist-packages/gavo/user/serve.py", line 169, in _configureTwistedLog
    theLog = logfile.LogFile("web.log", base.getConfig("logDir"))
  File "/usr/lib/python2.7/dist-packages/twisted/python/logfile.py", line 161, in __init__
    BaseLogFile.__init__(self, name, directory, defaultMode)
  File "/usr/lib/python2.7/dist-packages/twisted/python/logfile.py", line 40, in __init__
    self._openFile()
  File "/usr/lib/python2.7/dist-packages/twisted/python/logfile.py", line 166, in _openFile
    BaseLogFile._openFile(self)
  File "/usr/lib/python2.7/dist-packages/twisted/python/logfile.py", line 64, in _openFile
    self._file = file(self.path, "r+", 1)
IOError: [Errno 13] Permission denied: u'/home/gavo/LIRAE/LIRAE-DaCHS/logs/web.log'
2014-05-11 12:53:12,316 [ERROR 25935] Uncaught exception at toplevel
Traceback (most recent call last):
  File "/usr/lib/python2.7/dist-packages/gavo/user/cli.py", line 158, in main
    funcToRun()
  File "/usr/lib/python2.7/dist-packages/gavo/user/serve.py", line 323, in main
    args.subAction(args)
  File "/usr/lib/python2.7/dist-packages/gavo/user/serve.py", line 289, in restart
    start(args)
  File "/usr/lib/python2.7/dist-packages/gavo/user/serve.py", line 245, in start
    _startServer)
  File "/usr/lib/python2.7/dist-packages/gavo/user/serve.py", line 161, in daemonize
    callable()
  File "/usr/lib/python2.7/dist-packages/gavo/user/serve.py", line 224, in _startServer
    root.site.webLog = _configureTwistedLog()
  File "/usr/lib/python2.7/dist-packages/gavo/user/serve.py", line 169, in _configureTwistedLog
    theLog = logfile.LogFile("web.log", base.getConfig("logDir"))
  File "/usr/lib/python2.7/dist-packages/twisted/python/logfile.py", line 161, in __init__
    BaseLogFile.__init__(self, name, directory, defaultMode)
  File "/usr/lib/python2.7/dist-packages/twisted/python/logfile.py", line 40, in __init__
    self._openFile()
  File "/usr/lib/python2.7/dist-packages/twisted/python/logfile.py", line 166, in _openFile
    BaseLogFile._openFile(self)
  File "/usr/lib/python2.7/dist-packages/twisted/python/logfile.py", line 64, in _openFile
    self._file = file(self.path, "r+", 1)
IOError: [Errno 13] Permission denied: u'/home/gavo/LIRAE/LIRAE-DaCHS/logs/web.log'
2014-05-11 12:53:59,734 [ERROR 25952] Uncaught exception at toplevel
Traceback (most recent call last):
  File "/usr/lib/python2.7/dist-packages/gavo/user/cli.py", line 158, in main
    funcToRun()
  File "/usr/lib/python2.7/dist-packages/gavo/user/serve.py", line 323, in main
    args.subAction(args)
  File "/usr/lib/python2.7/dist-packages/gavo/user/serve.py", line 245, in start
    _startServer)
  File "/usr/lib/python2.7/dist-packages/gavo/user/serve.py", line 161, in daemonize
    callable()
  File "/usr/lib/python2.7/dist-packages/gavo/user/serve.py", line 224, in _startServer
    root.site.webLog = _configureTwistedLog()
  File "/usr/lib/python2.7/dist-packages/gavo/user/serve.py", line 169, in _configureTwistedLog
    theLog = logfile.LogFile("web.log", base.getConfig("logDir"))
  File "/usr/lib/python2.7/dist-packages/twisted/python/logfile.py", line 161, in __init__
    BaseLogFile.__init__(self, name, directory, defaultMode)
  File "/usr/lib/python2.7/dist-packages/twisted/python/logfile.py", line 40, in __init__
    self._openFile()
  File "/usr/lib/python2.7/dist-packages/twisted/python/logfile.py", line 166, in _openFile
    BaseLogFile._openFile(self)
  File "/usr/lib/python2.7/dist-packages/twisted/python/logfile.py", line 64, in _openFile
    self._file = file(self.path, "r+", 1)
IOError: [Errno 13] Permission denied: u'/home/gavo/LIRAE/LIRAE-DaCHS/logs/web.log'
2014-05-11 12:55:27,262 [ERROR 25964] Uncaught exception at toplevel
Traceback (most recent call last):
  File "/usr/lib/python2.7/dist-packages/gavo/user/cli.py", line 158, in main
    funcToRun()
  File "/usr/lib/python2.7/dist-packages/gavo/user/serve.py", line 323, in main
    args.subAction(args)
  File "/usr/lib/python2.7/dist-packages/gavo/user/serve.py", line 289, in restart
    start(args)
  File "/usr/lib/python2.7/dist-packages/gavo/user/serve.py", line 245, in start
    _startServer)
  File "/usr/lib/python2.7/dist-packages/gavo/user/serve.py", line 161, in daemonize
    callable()
  File "/usr/lib/python2.7/dist-packages/gavo/user/serve.py", line 224, in _startServer
    root.site.webLog = _configureTwistedLog()
  File "/usr/lib/python2.7/dist-packages/gavo/user/serve.py", line 169, in _configureTwistedLog
    theLog = logfile.LogFile("web.log", base.getConfig("logDir"))
  File "/usr/lib/python2.7/dist-packages/twisted/python/logfile.py", line 161, in __init__
    BaseLogFile.__init__(self, name, directory, defaultMode)
  File "/usr/lib/python2.7/dist-packages/twisted/python/logfile.py", line 40, in __init__
    self._openFile()
  File "/usr/lib/python2.7/dist-packages/twisted/python/logfile.py", line 166, in _openFile
    BaseLogFile._openFile(self)
  File "/usr/lib/python2.7/dist-packages/twisted/python/logfile.py", line 64, in _openFile
    self._file = file(self.path, "r+", 1)
IOError: [Errno 13] Permission denied: u'/home/gavo/LIRAE/LIRAE-DaCHS/logs/web.log'
2014-05-11 12:57:15,198 [ERROR 26043] Uncaught exception at toplevel
Traceback (most recent call last):
  File "/usr/lib/python2.7/dist-packages/gavo/user/cli.py", line 158, in main
    funcToRun()
  File "/usr/lib/python2.7/dist-packages/gavo/user/serve.py", line 323, in main
    args.subAction(args)
  File "/usr/lib/python2.7/dist-packages/gavo/user/serve.py", line 289, in restart
    start(args)
  File "/usr/lib/python2.7/dist-packages/gavo/user/serve.py", line 245, in start
    _startServer)
  File "/usr/lib/python2.7/dist-packages/gavo/user/serve.py", line 161, in daemonize
    callable()
  File "/usr/lib/python2.7/dist-packages/gavo/user/serve.py", line 224, in _startServer
    root.site.webLog = _configureTwistedLog()
  File "/usr/lib/python2.7/dist-packages/gavo/user/serve.py", line 169, in _configureTwistedLog
    theLog = logfile.LogFile("web.log", base.getConfig("logDir"))
  File "/usr/lib/python2.7/dist-packages/twisted/python/logfile.py", line 161, in __init__
    BaseLogFile.__init__(self, name, directory, defaultMode)
  File "/usr/lib/python2.7/dist-packages/twisted/python/logfile.py", line 40, in __init__
    self._openFile()
  File "/usr/lib/python2.7/dist-packages/twisted/python/logfile.py", line 166, in _openFile
    BaseLogFile._openFile(self)
  File "/usr/lib/python2.7/dist-packages/twisted/python/logfile.py", line 64, in _openFile
    self._file = file(self.path, "r+", 1)
IOError: [Errno 13] Permission denied: u'/home/gavo/LIRAE/LIRAE-DaCHS/logs/web.log'
2014-05-12 17:04:08,865 [ERROR 30357] Uncaught exception at toplevel
Traceback (most recent call last):
  File "/usr/lib/python2.7/dist-packages/gavo/user/cli.py", line 158, in main
    funcToRun()
  File "/usr/lib/python2.7/dist-packages/gavo/user/serve.py", line 323, in main
    args.subAction(args)
  File "/usr/lib/python2.7/dist-packages/gavo/user/serve.py", line 289, in restart
    start(args)
  File "/usr/lib/python2.7/dist-packages/gavo/user/serve.py", line 245, in start
    _startServer)
  File "/usr/lib/python2.7/dist-packages/gavo/user/serve.py", line 161, in daemonize
    callable()
  File "/usr/lib/python2.7/dist-packages/gavo/user/serve.py", line 224, in _startServer
    root.site.webLog = _configureTwistedLog()
  File "/usr/lib/python2.7/dist-packages/gavo/user/serve.py", line 169, in _configureTwistedLog
    theLog = logfile.LogFile("web.log", base.getConfig("logDir"))
  File "/usr/lib/python2.7/dist-packages/twisted/python/logfile.py", line 161, in __init__
    BaseLogFile.__init__(self, name, directory, defaultMode)
  File "/usr/lib/python2.7/dist-packages/twisted/python/logfile.py", line 40, in __init__
    self._openFile()
  File "/usr/lib/python2.7/dist-packages/twisted/python/logfile.py", line 166, in _openFile
    BaseLogFile._openFile(self)
  File "/usr/lib/python2.7/dist-packages/twisted/python/logfile.py", line 64, in _openFile
    self._file = file(self.path, "r+", 1)
IOError: [Errno 13] Permission denied: u'/home/gavo/LIRAE/LIRAE-DaCHS/logs/web.log'
2014-05-26 16:14:44,272 [ERROR 2066] Uncaught exception at toplevel
Traceback (most recent call last):
  File "/usr/lib/python2.7/dist-packages/gavo/user/cli.py", line 158, in main
    funcToRun()
  File "/usr/lib/python2.7/dist-packages/gavo/user/serve.py", line 323, in main
    args.subAction(args)
  File "/usr/lib/python2.7/dist-packages/gavo/user/serve.py", line 245, in start
    _startServer)
  File "/usr/lib/python2.7/dist-packages/gavo/user/serve.py", line 161, in daemonize
    callable()
  File "/usr/lib/python2.7/dist-packages/gavo/user/serve.py", line 224, in _startServer
    root.site.webLog = _configureTwistedLog()
  File "/usr/lib/python2.7/dist-packages/gavo/user/serve.py", line 169, in _configureTwistedLog
    theLog = logfile.LogFile("web.log", base.getConfig("logDir"))
  File "/usr/lib/python2.7/dist-packages/twisted/python/logfile.py", line 161, in __init__
    BaseLogFile.__init__(self, name, directory, defaultMode)
  File "/usr/lib/python2.7/dist-packages/twisted/python/logfile.py", line 40, in __init__
    self._openFile()
  File "/usr/lib/python2.7/dist-packages/twisted/python/logfile.py", line 166, in _openFile
    BaseLogFile._openFile(self)
  File "/usr/lib/python2.7/dist-packages/twisted/python/logfile.py", line 64, in _openFile
    self._file = file(self.path, "r+", 1)
IOError: [Errno 13] Permission denied: u'/home/gavo/LIRAE/LIRAE-DaCHS/logs/web.log'
2014-05-26 16:30:46,271 [ERROR 2084] Uncaught exception at toplevel
Traceback (most recent call last):
  File "/usr/lib/python2.7/dist-packages/gavo/user/cli.py", line 158, in main
    funcToRun()
  File "/usr/lib/python2.7/dist-packages/gavo/user/serve.py", line 323, in main
    args.subAction(args)
  File "/usr/lib/python2.7/dist-packages/gavo/user/serve.py", line 245, in start
    _startServer)
  File "/usr/lib/python2.7/dist-packages/gavo/user/serve.py", line 161, in daemonize
    callable()
  File "/usr/lib/python2.7/dist-packages/gavo/user/serve.py", line 224, in _startServer
    root.site.webLog = _configureTwistedLog()
  File "/usr/lib/python2.7/dist-packages/gavo/user/serve.py", line 169, in _configureTwistedLog
    theLog = logfile.LogFile("web.log", base.getConfig("logDir"))
  File "/usr/lib/python2.7/dist-packages/twisted/python/logfile.py", line 161, in __init__
    BaseLogFile.__init__(self, name, directory, defaultMode)
  File "/usr/lib/python2.7/dist-packages/twisted/python/logfile.py", line 40, in __init__
    self._openFile()
  File "/usr/lib/python2.7/dist-packages/twisted/python/logfile.py", line 166, in _openFile
    BaseLogFile._openFile(self)
  File "/usr/lib/python2.7/dist-packages/twisted/python/logfile.py", line 64, in _openFile
    self._file = file(self.path, "r+", 1)
IOError: [Errno 13] Permission denied: u'/home/gavo/LIRAE/LIRAE-DaCHS/logs/web.log'
2014-05-29 03:59:21,066 [ERROR 2081] Uncaught exception at toplevel
Traceback (most recent call last):
  File "/usr/lib/python2.7/dist-packages/gavo/user/cli.py", line 158, in main
    funcToRun()
  File "/usr/lib/python2.7/dist-packages/gavo/user/serve.py", line 323, in main
    args.subAction(args)
  File "/usr/lib/python2.7/dist-packages/gavo/user/serve.py", line 245, in start
    _startServer)
  File "/usr/lib/python2.7/dist-packages/gavo/user/serve.py", line 161, in daemonize
    callable()
  File "/usr/lib/python2.7/dist-packages/gavo/user/serve.py", line 224, in _startServer
    root.site.webLog = _configureTwistedLog()
  File "/usr/lib/python2.7/dist-packages/gavo/user/serve.py", line 169, in _configureTwistedLog
    theLog = logfile.LogFile("web.log", base.getConfig("logDir"))
  File "/usr/lib/python2.7/dist-packages/twisted/python/logfile.py", line 161, in __init__
    BaseLogFile.__init__(self, name, directory, defaultMode)
  File "/usr/lib/python2.7/dist-packages/twisted/python/logfile.py", line 40, in __init__
    self._openFile()
  File "/usr/lib/python2.7/dist-packages/twisted/python/logfile.py", line 166, in _openFile
    BaseLogFile._openFile(self)
  File "/usr/lib/python2.7/dist-packages/twisted/python/logfile.py", line 64, in _openFile
    self._file = file(self.path, "r+", 1)
IOError: [Errno 13] Permission denied: u'/home/gavo/LIRAE/LIRAE-DaCHS/logs/web.log'
2014-06-02 17:51:13,232 [ERROR 2033] Uncaught exception at toplevel
Traceback (most recent call last):
  File "/usr/lib/python2.7/dist-packages/gavo/user/cli.py", line 158, in main
    funcToRun()
  File "/usr/lib/python2.7/dist-packages/gavo/user/serve.py", line 323, in main
    args.subAction(args)
  File "/usr/lib/python2.7/dist-packages/gavo/user/serve.py", line 245, in start
    _startServer)
  File "/usr/lib/python2.7/dist-packages/gavo/user/serve.py", line 161, in daemonize
    callable()
  File "/usr/lib/python2.7/dist-packages/gavo/user/serve.py", line 224, in _startServer
    root.site.webLog = _configureTwistedLog()
  File "/usr/lib/python2.7/dist-packages/gavo/user/serve.py", line 169, in _configureTwistedLog
    theLog = logfile.LogFile("web.log", base.getConfig("logDir"))
  File "/usr/lib/python2.7/dist-packages/twisted/python/logfile.py", line 161, in __init__
    BaseLogFile.__init__(self, name, directory, defaultMode)
  File "/usr/lib/python2.7/dist-packages/twisted/python/logfile.py", line 40, in __init__
    self._openFile()
  File "/usr/lib/python2.7/dist-packages/twisted/python/logfile.py", line 166, in _openFile
    BaseLogFile._openFile(self)
  File "/usr/lib/python2.7/dist-packages/twisted/python/logfile.py", line 64, in _openFile
    self._file = file(self.path, "r+", 1)
IOError: [Errno 13] Permission denied: u'/home/gavo/LIRAE/LIRAE-DaCHS/logs/web.log'
2014-06-03 02:28:00,132 [ERROR 2033] Uncaught exception at toplevel
Traceback (most recent call last):
  File "/usr/lib/python2.7/dist-packages/gavo/user/cli.py", line 158, in main
    funcToRun()
  File "/usr/lib/python2.7/dist-packages/gavo/user/serve.py", line 323, in main
    args.subAction(args)
  File "/usr/lib/python2.7/dist-packages/gavo/user/serve.py", line 245, in start
    _startServer)
  File "/usr/lib/python2.7/dist-packages/gavo/user/serve.py", line 161, in daemonize
    callable()
  File "/usr/lib/python2.7/dist-packages/gavo/user/serve.py", line 224, in _startServer
    root.site.webLog = _configureTwistedLog()
  File "/usr/lib/python2.7/dist-packages/gavo/user/serve.py", line 169, in _configureTwistedLog
    theLog = logfile.LogFile("web.log", base.getConfig("logDir"))
  File "/usr/lib/python2.7/dist-packages/twisted/python/logfile.py", line 161, in __init__
    BaseLogFile.__init__(self, name, directory, defaultMode)
  File "/usr/lib/python2.7/dist-packages/twisted/python/logfile.py", line 40, in __init__
    self._openFile()
  File "/usr/lib/python2.7/dist-packages/twisted/python/logfile.py", line 166, in _openFile
    BaseLogFile._openFile(self)
  File "/usr/lib/python2.7/dist-packages/twisted/python/logfile.py", line 64, in _openFile
    self._file = file(self.path, "r+", 1)
IOError: [Errno 13] Permission denied: u'/home/gavo/LIRAE/LIRAE-DaCHS/logs/web.log'
2014-06-04 12:20:40,204 [ERROR 2029] Uncaught exception at toplevel
Traceback (most recent call last):
  File "/usr/lib/python2.7/dist-packages/gavo/user/cli.py", line 158, in main
    funcToRun()
  File "/usr/lib/python2.7/dist-packages/gavo/user/serve.py", line 323, in main
    args.subAction(args)
  File "/usr/lib/python2.7/dist-packages/gavo/user/serve.py", line 245, in start
    _startServer)
  File "/usr/lib/python2.7/dist-packages/gavo/user/serve.py", line 161, in daemonize
    callable()
  File "/usr/lib/python2.7/dist-packages/gavo/user/serve.py", line 224, in _startServer
    root.site.webLog = _configureTwistedLog()
  File "/usr/lib/python2.7/dist-packages/gavo/user/serve.py", line 169, in _configureTwistedLog
    theLog = logfile.LogFile("web.log", base.getConfig("logDir"))
  File "/usr/lib/python2.7/dist-packages/twisted/python/logfile.py", line 161, in __init__
    BaseLogFile.__init__(self, name, directory, defaultMode)
  File "/usr/lib/python2.7/dist-packages/twisted/python/logfile.py", line 40, in __init__
    self._openFile()
  File "/usr/lib/python2.7/dist-packages/twisted/python/logfile.py", line 166, in _openFile
    BaseLogFile._openFile(self)
  File "/usr/lib/python2.7/dist-packages/twisted/python/logfile.py", line 64, in _openFile
    self._file = file(self.path, "r+", 1)
IOError: [Errno 13] Permission denied: u'/home/gavo/LIRAE/LIRAE-DaCHS/logs/web.log'
2014-06-04 12:51:00,272 [ERROR 2034] Uncaught exception at toplevel
Traceback (most recent call last):
  File "/usr/lib/python2.7/dist-packages/gavo/user/cli.py", line 158, in main
    funcToRun()
  File "/usr/lib/python2.7/dist-packages/gavo/user/serve.py", line 323, in main
    args.subAction(args)
  File "/usr/lib/python2.7/dist-packages/gavo/user/serve.py", line 245, in start
    _startServer)
  File "/usr/lib/python2.7/dist-packages/gavo/user/serve.py", line 161, in daemonize
    callable()
  File "/usr/lib/python2.7/dist-packages/gavo/user/serve.py", line 224, in _startServer
    root.site.webLog = _configureTwistedLog()
  File "/usr/lib/python2.7/dist-packages/gavo/user/serve.py", line 169, in _configureTwistedLog
    theLog = logfile.LogFile("web.log", base.getConfig("logDir"))
  File "/usr/lib/python2.7/dist-packages/twisted/python/logfile.py", line 161, in __init__
    BaseLogFile.__init__(self, name, directory, defaultMode)
  File "/usr/lib/python2.7/dist-packages/twisted/python/logfile.py", line 40, in __init__
    self._openFile()
  File "/usr/lib/python2.7/dist-packages/twisted/python/logfile.py", line 166, in _openFile
    BaseLogFile._openFile(self)
  File "/usr/lib/python2.7/dist-packages/twisted/python/logfile.py", line 64, in _openFile
    self._file = file(self.path, "r+", 1)
IOError: [Errno 13] Permission denied: u'/home/gavo/LIRAE/LIRAE-DaCHS/logs/web.log'
2014-06-04 15:56:16,173 [ERROR 2036] Uncaught exception at toplevel
Traceback (most recent call last):
  File "/usr/lib/python2.7/dist-packages/gavo/user/cli.py", line 158, in main
    funcToRun()
  File "/usr/lib/python2.7/dist-packages/gavo/user/serve.py", line 323, in main
    args.subAction(args)
  File "/usr/lib/python2.7/dist-packages/gavo/user/serve.py", line 245, in start
    _startServer)
  File "/usr/lib/python2.7/dist-packages/gavo/user/serve.py", line 161, in daemonize
    callable()
  File "/usr/lib/python2.7/dist-packages/gavo/user/serve.py", line 224, in _startServer
    root.site.webLog = _configureTwistedLog()
  File "/usr/lib/python2.7/dist-packages/gavo/user/serve.py", line 169, in _configureTwistedLog
    theLog = logfile.LogFile("web.log", base.getConfig("logDir"))
  File "/usr/lib/python2.7/dist-packages/twisted/python/logfile.py", line 161, in __init__
    BaseLogFile.__init__(self, name, directory, defaultMode)
  File "/usr/lib/python2.7/dist-packages/twisted/python/logfile.py", line 40, in __init__
    self._openFile()
  File "/usr/lib/python2.7/dist-packages/twisted/python/logfile.py", line 166, in _openFile
    BaseLogFile._openFile(self)
  File "/usr/lib/python2.7/dist-packages/twisted/python/logfile.py", line 64, in _openFile
    self._file = file(self.path, "r+", 1)
IOError: [Errno 13] Permission denied: u'/home/gavo/LIRAE/LIRAE-DaCHS/logs/web.log'
2014-06-05 17:33:04,179 [ERROR 2062] Uncaught exception at toplevel
Traceback (most recent call last):
  File "/usr/lib/python2.7/dist-packages/gavo/user/cli.py", line 158, in main
    funcToRun()
  File "/usr/lib/python2.7/dist-packages/gavo/user/serve.py", line 323, in main
    args.subAction(args)
  File "/usr/lib/python2.7/dist-packages/gavo/user/serve.py", line 245, in start
    _startServer)
  File "/usr/lib/python2.7/dist-packages/gavo/user/serve.py", line 161, in daemonize
    callable()
  File "/usr/lib/python2.7/dist-packages/gavo/user/serve.py", line 224, in _startServer
    root.site.webLog = _configureTwistedLog()
  File "/usr/lib/python2.7/dist-packages/gavo/user/serve.py", line 169, in _configureTwistedLog
    theLog = logfile.LogFile("web.log", base.getConfig("logDir"))
  File "/usr/lib/python2.7/dist-packages/twisted/python/logfile.py", line 161, in __init__
    BaseLogFile.__init__(self, name, directory, defaultMode)
  File "/usr/lib/python2.7/dist-packages/twisted/python/logfile.py", line 40, in __init__
    self._openFile()
  File "/usr/lib/python2.7/dist-packages/twisted/python/logfile.py", line 166, in _openFile
    BaseLogFile._openFile(self)
  File "/usr/lib/python2.7/dist-packages/twisted/python/logfile.py", line 64, in _openFile
    self._file = file(self.path, "r+", 1)
IOError: [Errno 13] Permission denied: u'/home/gavo/LIRAE/LIRAE-DaCHS/logs/web.log'
2014-06-05 17:53:26,249 [ERROR 2064] Uncaught exception at toplevel
Traceback (most recent call last):
  File "/usr/lib/python2.7/dist-packages/gavo/user/cli.py", line 158, in main
    funcToRun()
  File "/usr/lib/python2.7/dist-packages/gavo/user/serve.py", line 323, in main
    args.subAction(args)
  File "/usr/lib/python2.7/dist-packages/gavo/user/serve.py", line 245, in start
    _startServer)
  File "/usr/lib/python2.7/dist-packages/gavo/user/serve.py", line 161, in daemonize
    callable()
  File "/usr/lib/python2.7/dist-packages/gavo/user/serve.py", line 224, in _startServer
    root.site.webLog = _configureTwistedLog()
  File "/usr/lib/python2.7/dist-packages/gavo/user/serve.py", line 169, in _configureTwistedLog
    theLog = logfile.LogFile("web.log", base.getConfig("logDir"))
  File "/usr/lib/python2.7/dist-packages/twisted/python/logfile.py", line 161, in __init__
    BaseLogFile.__init__(self, name, directory, defaultMode)
  File "/usr/lib/python2.7/dist-packages/twisted/python/logfile.py", line 40, in __init__
    self._openFile()
  File "/usr/lib/python2.7/dist-packages/twisted/python/logfile.py", line 166, in _openFile
    BaseLogFile._openFile(self)
  File "/usr/lib/python2.7/dist-packages/twisted/python/logfile.py", line 64, in _openFile
    self._file = file(self.path, "r+", 1)
IOError: [Errno 13] Permission denied: u'/home/gavo/LIRAE/LIRAE-DaCHS/logs/web.log'
2014-06-05 23:05:09,165 [ERROR 2091] Uncaught exception at toplevel
Traceback (most recent call last):
  File "/usr/lib/python2.7/dist-packages/gavo/user/cli.py", line 158, in main
    funcToRun()
  File "/usr/lib/python2.7/dist-packages/gavo/user/serve.py", line 323, in main
    args.subAction(args)
  File "/usr/lib/python2.7/dist-packages/gavo/user/serve.py", line 245, in start
    _startServer)
  File "/usr/lib/python2.7/dist-packages/gavo/user/serve.py", line 161, in daemonize
    callable()
  File "/usr/lib/python2.7/dist-packages/gavo/user/serve.py", line 224, in _startServer
    root.site.webLog = _configureTwistedLog()
  File "/usr/lib/python2.7/dist-packages/gavo/user/serve.py", line 169, in _configureTwistedLog
    theLog = logfile.LogFile("web.log", base.getConfig("logDir"))
  File "/usr/lib/python2.7/dist-packages/twisted/python/logfile.py", line 161, in __init__
    BaseLogFile.__init__(self, name, directory, defaultMode)
  File "/usr/lib/python2.7/dist-packages/twisted/python/logfile.py", line 40, in __init__
    self._openFile()
  File "/usr/lib/python2.7/dist-packages/twisted/python/logfile.py", line 166, in _openFile
    BaseLogFile._openFile(self)
  File "/usr/lib/python2.7/dist-packages/twisted/python/logfile.py", line 64, in _openFile
    self._file = file(self.path, "r+", 1)
IOError: [Errno 13] Permission denied: u'/home/gavo/LIRAE/LIRAE-DaCHS/logs/web.log'
2014-06-06 14:42:21,457 [ERROR 5539] Uncaught exception at toplevel
Traceback (most recent call last):
  File "/usr/lib/python2.7/dist-packages/gavo/user/cli.py", line 158, in main
    funcToRun()
  File "/usr/lib/python2.7/dist-packages/gavo/user/serve.py", line 323, in main
    args.subAction(args)
  File "/usr/lib/python2.7/dist-packages/gavo/user/serve.py", line 245, in start
    _startServer)
  File "/usr/lib/python2.7/dist-packages/gavo/user/serve.py", line 161, in daemonize
    callable()
  File "/usr/lib/python2.7/dist-packages/gavo/user/serve.py", line 224, in _startServer
    root.site.webLog = _configureTwistedLog()
  File "/usr/lib/python2.7/dist-packages/gavo/user/serve.py", line 169, in _configureTwistedLog
    theLog = logfile.LogFile("web.log", base.getConfig("logDir"))
  File "/usr/lib/python2.7/dist-packages/twisted/python/logfile.py", line 161, in __init__
    BaseLogFile.__init__(self, name, directory, defaultMode)
  File "/usr/lib/python2.7/dist-packages/twisted/python/logfile.py", line 40, in __init__
    self._openFile()
  File "/usr/lib/python2.7/dist-packages/twisted/python/logfile.py", line 166, in _openFile
    BaseLogFile._openFile(self)
  File "/usr/lib/python2.7/dist-packages/twisted/python/logfile.py", line 64, in _openFile
    self._file = file(self.path, "r+", 1)
IOError: [Errno 13] Permission denied: u'/home/gavo/LIRAE/LIRAE-DaCHS/logs/web.log'
2014-06-06 14:48:35,886 [ERROR 5557] Uncaught exception at toplevel
Traceback (most recent call last):
  File "/usr/lib/python2.7/dist-packages/gavo/user/cli.py", line 158, in main
    funcToRun()
  File "/usr/lib/python2.7/dist-packages/gavo/user/serve.py", line 323, in main
    args.subAction(args)
  File "/usr/lib/python2.7/dist-packages/gavo/user/serve.py", line 245, in start
    _startServer)
  File "/usr/lib/python2.7/dist-packages/gavo/user/serve.py", line 161, in daemonize
    callable()
  File "/usr/lib/python2.7/dist-packages/gavo/user/serve.py", line 224, in _startServer
    root.site.webLog = _configureTwistedLog()
  File "/usr/lib/python2.7/dist-packages/gavo/user/serve.py", line 169, in _configureTwistedLog
    theLog = logfile.LogFile("web.log", base.getConfig("logDir"))
  File "/usr/lib/python2.7/dist-packages/twisted/python/logfile.py", line 161, in __init__
    BaseLogFile.__init__(self, name, directory, defaultMode)
  File "/usr/lib/python2.7/dist-packages/twisted/python/logfile.py", line 40, in __init__
    self._openFile()
  File "/usr/lib/python2.7/dist-packages/twisted/python/logfile.py", line 166, in _openFile
    BaseLogFile._openFile(self)
  File "/usr/lib/python2.7/dist-packages/twisted/python/logfile.py", line 64, in _openFile
    self._file = file(self.path, "r+", 1)
IOError: [Errno 13] Permission denied: u'/home/gavo/LIRAE/LIRAE-DaCHS/logs/web.log'
2014-07-07 22:12:04,627 [ERROR 10066] Uncaught exception at toplevel
Traceback (most recent call last):
  File "/usr/lib/python2.7/dist-packages/gavo/user/cli.py", line 158, in main
    funcToRun()
  File "/usr/lib/python2.7/dist-packages/gavo/user/serve.py", line 323, in main
    args.subAction(args)
  File "/usr/lib/python2.7/dist-packages/gavo/user/serve.py", line 289, in restart
    start(args)
  File "/usr/lib/python2.7/dist-packages/gavo/user/serve.py", line 245, in start
    _startServer)
  File "/usr/lib/python2.7/dist-packages/gavo/user/serve.py", line 161, in daemonize
    callable()
  File "/usr/lib/python2.7/dist-packages/gavo/user/serve.py", line 224, in _startServer
    root.site.webLog = _configureTwistedLog()
  File "/usr/lib/python2.7/dist-packages/gavo/user/serve.py", line 169, in _configureTwistedLog
    theLog = logfile.LogFile("web.log", base.getConfig("logDir"))
  File "/usr/lib/python2.7/dist-packages/twisted/python/logfile.py", line 161, in __init__
    BaseLogFile.__init__(self, name, directory, defaultMode)
  File "/usr/lib/python2.7/dist-packages/twisted/python/logfile.py", line 40, in __init__
    self._openFile()
  File "/usr/lib/python2.7/dist-packages/twisted/python/logfile.py", line 166, in _openFile
    BaseLogFile._openFile(self)
  File "/usr/lib/python2.7/dist-packages/twisted/python/logfile.py", line 64, in _openFile
    self._file = file(self.path, "r+", 1)
IOError: [Errno 13] Permission denied: u'/home/gavo/LIRAE/LIRAE-DaCHS/logs/web.log'
2014-09-14 22:02:20,337 [ERROR 2097] Uncaught exception at toplevel
Traceback (most recent call last):
  File "/usr/lib/python2.7/dist-packages/gavo/user/cli.py", line 158, in main
    funcToRun()
  File "/usr/lib/python2.7/dist-packages/gavo/user/serve.py", line 323, in main
    args.subAction(args)
  File "/usr/lib/python2.7/dist-packages/gavo/user/serve.py", line 245, in start
    _startServer)
  File "/usr/lib/python2.7/dist-packages/gavo/user/serve.py", line 161, in daemonize
    callable()
  File "/usr/lib/python2.7/dist-packages/gavo/user/serve.py", line 224, in _startServer
    root.site.webLog = _configureTwistedLog()
  File "/usr/lib/python2.7/dist-packages/gavo/user/serve.py", line 169, in _configureTwistedLog
    theLog = logfile.LogFile("web.log", base.getConfig("logDir"))
  File "/usr/lib/python2.7/dist-packages/twisted/python/logfile.py", line 161, in __init__
    BaseLogFile.__init__(self, name, directory, defaultMode)
  File "/usr/lib/python2.7/dist-packages/twisted/python/logfile.py", line 40, in __init__
    self._openFile()
  File "/usr/lib/python2.7/dist-packages/twisted/python/logfile.py", line 166, in _openFile
    BaseLogFile._openFile(self)
  File "/usr/lib/python2.7/dist-packages/twisted/python/logfile.py", line 64, in _openFile
    self._file = file(self.path, "r+", 1)
IOError: [Errno 13] Permission denied: u'/home/gavo/LIRAE/LIRAE-DaCHS/logs/web.log'
2014-09-14 22:13:54,792 [ERROR 2166] Uncaught exception at toplevel
Traceback (most recent call last):
  File "/usr/lib/python2.7/dist-packages/gavo/user/cli.py", line 158, in main
    funcToRun()
  File "/usr/lib/python2.7/dist-packages/gavo/user/serve.py", line 323, in main
    args.subAction(args)
  File "/usr/lib/python2.7/dist-packages/gavo/user/serve.py", line 245, in start
    _startServer)
  File "/usr/lib/python2.7/dist-packages/gavo/user/serve.py", line 161, in daemonize
    callable()
  File "/usr/lib/python2.7/dist-packages/gavo/user/serve.py", line 224, in _startServer
    root.site.webLog = _configureTwistedLog()
  File "/usr/lib/python2.7/dist-packages/gavo/user/serve.py", line 169, in _configureTwistedLog
    theLog = logfile.LogFile("web.log", base.getConfig("logDir"))
  File "/usr/lib/python2.7/dist-packages/twisted/python/logfile.py", line 161, in __init__
    BaseLogFile.__init__(self, name, directory, defaultMode)
  File "/usr/lib/python2.7/dist-packages/twisted/python/logfile.py", line 40, in __init__
    self._openFile()
  File "/usr/lib/python2.7/dist-packages/twisted/python/logfile.py", line 166, in _openFile
    BaseLogFile._openFile(self)
  File "/usr/lib/python2.7/dist-packages/twisted/python/logfile.py", line 64, in _openFile
    self._file = file(self.path, "r+", 1)
IOError: [Errno 13] Permission denied: u'/home/gavo/LIRAE/LIRAE-DaCHS/logs/web.log'
2014-10-02 09:50:12,840 [ERROR 16940] Uncaught exception at toplevel
Traceback (most recent call last):
  File "/usr/lib/python2.7/dist-packages/gavo/user/cli.py", line 158, in main
    funcToRun()
  File "/usr/lib/python2.7/dist-packages/gavo/user/serve.py", line 342, in main
    args.subAction(args)
  File "/usr/lib/python2.7/dist-packages/gavo/user/serve.py", line 307, in restart
    start(args)
  File "/usr/lib/python2.7/dist-packages/gavo/user/serve.py", line 261, in start
    _startServer)
  File "/usr/lib/python2.7/dist-packages/gavo/user/serve.py", line 159, in daemonize
    callable()
  File "/usr/lib/python2.7/dist-packages/gavo/user/serve.py", line 234, in _startServer
    root.site.webLog = _configureTwistedLog()
  File "/usr/lib/python2.7/dist-packages/gavo/user/serve.py", line 167, in _configureTwistedLog
    theLog = logfile.LogFile("web.log", base.getConfig("logDir"))
  File "/usr/lib/python2.7/dist-packages/twisted/python/logfile.py", line 161, in __init__
    BaseLogFile.__init__(self, name, directory, defaultMode)
  File "/usr/lib/python2.7/dist-packages/twisted/python/logfile.py", line 40, in __init__
    self._openFile()
  File "/usr/lib/python2.7/dist-packages/twisted/python/logfile.py", line 166, in _openFile
    BaseLogFile._openFile(self)
  File "/usr/lib/python2.7/dist-packages/twisted/python/logfile.py", line 64, in _openFile
    self._file = file(self.path, "r+", 1)
IOError: [Errno 13] Permission denied: u'/home/gavo/LIRAE/LIRAE-DaCHS/logs/web.log'
2014-10-02 10:09:58,736 [ERROR 17447] Uncaught exception at toplevel
Traceback (most recent call last):
  File "/usr/lib/python2.7/dist-packages/gavo/user/cli.py", line 158, in main
    funcToRun()
  File "/usr/lib/python2.7/dist-packages/gavo/user/importing.py", line 153, in main
    sys.exit(process(opts, args))
  File "/usr/lib/python2.7/dist-packages/gavo/user/importing.py", line 79, in process
    rsc.makeDependentsFor(dds, opts, connection)
  File "/usr/lib/python2.7/dist-packages/gavo/rsc/data.py", line 498, in makeDependentsFor
    makeData(dd, parseOptions=parseOptions, connection=connection)
  File "/usr/lib/python2.7/dist-packages/gavo/rsc/data.py", line 451, in makeData
    processSource(res, forceSource, feeder, parseOptions, connection)
  File "/usr/lib/python2.7/dist-packages/gavo/rsc/data.py", line 177, in __exit__
    self._exitSuccess()
  File "/usr/lib/python2.7/dist-packages/gavo/rsc/data.py", line 161, in _exitSuccess
    feeder.__exit__(None, None, None)
  File "/usr/lib/python2.7/dist-packages/gavo/rsc/dbtable.py", line 105, in __exit__
    table._Feeder.__exit__(self, *args)
  File "/usr/lib/python2.7/dist-packages/gavo/rsc/table.py", line 91, in __exit__
    self.table.importFinished()
  File "/usr/lib/python2.7/dist-packages/gavo/rsc/dbtable.py", line 657, in importFinished
    self.runScripts("postCreation")
  File "/usr/lib/python2.7/dist-packages/gavo/rsc/table.py", line 196, in runScripts
    self._runScripts(self, phase, **kwargs)
  File "/usr/lib/python2.7/dist-packages/gavo/rscdef/scripting.py", line 252, in runScripts
    runner.run(table, **kwargs)
  File "/usr/lib/python2.7/dist-packages/gavo/rscdef/scripting.py", line 178, in run
    func(dbTable, **kwargs)
  File "<string>", line 11, in scriptFun
  File "/usr/lib/python2.7/dist-packages/gavo/rsc/dbtable.py", line 543, in query
    return DBMethodsMixin.query(self, query, data)
  File "/usr/lib/python2.7/dist-packages/gavo/base/sqlsupport.py", line 735, in query
    cursor.execute(query, data)
ProgrammingError: syntax error at or near "AS"
LINE 56:       CAST( AS double precision) AS em_res_power,
                     ^

2014-10-02 10:11:18,732 [ERROR 17454] Uncaught exception at toplevel
Traceback (most recent call last):
  File "/usr/lib/python2.7/dist-packages/gavo/user/cli.py", line 158, in main
    funcToRun()
  File "/usr/lib/python2.7/dist-packages/gavo/user/importing.py", line 153, in main
    sys.exit(process(opts, args))
  File "/usr/lib/python2.7/dist-packages/gavo/user/importing.py", line 79, in process
    rsc.makeDependentsFor(dds, opts, connection)
  File "/usr/lib/python2.7/dist-packages/gavo/rsc/data.py", line 498, in makeDependentsFor
    makeData(dd, parseOptions=parseOptions, connection=connection)
  File "/usr/lib/python2.7/dist-packages/gavo/rsc/data.py", line 451, in makeData
    processSource(res, forceSource, feeder, parseOptions, connection)
  File "/usr/lib/python2.7/dist-packages/gavo/rsc/data.py", line 177, in __exit__
    self._exitSuccess()
  File "/usr/lib/python2.7/dist-packages/gavo/rsc/data.py", line 161, in _exitSuccess
    feeder.__exit__(None, None, None)
  File "/usr/lib/python2.7/dist-packages/gavo/rsc/dbtable.py", line 105, in __exit__
    table._Feeder.__exit__(self, *args)
  File "/usr/lib/python2.7/dist-packages/gavo/rsc/table.py", line 91, in __exit__
    self.table.importFinished()
  File "/usr/lib/python2.7/dist-packages/gavo/rsc/dbtable.py", line 657, in importFinished
    self.runScripts("postCreation")
  File "/usr/lib/python2.7/dist-packages/gavo/rsc/table.py", line 196, in runScripts
    self._runScripts(self, phase, **kwargs)
  File "/usr/lib/python2.7/dist-packages/gavo/rscdef/scripting.py", line 252, in runScripts
    runner.run(table, **kwargs)
  File "/usr/lib/python2.7/dist-packages/gavo/rscdef/scripting.py", line 178, in run
    func(dbTable, **kwargs)
  File "<string>", line 11, in scriptFun
  File "/usr/lib/python2.7/dist-packages/gavo/rsc/dbtable.py", line 543, in query
    return DBMethodsMixin.query(self, query, data)
  File "/usr/lib/python2.7/dist-packages/gavo/base/sqlsupport.py", line 735, in query
    cursor.execute(query, data)
ProgrammingError: syntax error at or near "AS"
LINE 56:       CAST( AS double precision) AS em_res_power,
                     ^

2014-10-02 10:12:11,592 [ERROR 17458] Uncaught exception at toplevel
Traceback (most recent call last):
  File "/usr/lib/python2.7/dist-packages/gavo/user/cli.py", line 158, in main
    funcToRun()
  File "/usr/lib/python2.7/dist-packages/gavo/user/importing.py", line 153, in main
    sys.exit(process(opts, args))
  File "/usr/lib/python2.7/dist-packages/gavo/user/importing.py", line 79, in process
    rsc.makeDependentsFor(dds, opts, connection)
  File "/usr/lib/python2.7/dist-packages/gavo/rsc/data.py", line 498, in makeDependentsFor
    makeData(dd, parseOptions=parseOptions, connection=connection)
  File "/usr/lib/python2.7/dist-packages/gavo/rsc/data.py", line 451, in makeData
    processSource(res, forceSource, feeder, parseOptions, connection)
  File "/usr/lib/python2.7/dist-packages/gavo/rsc/data.py", line 177, in __exit__
    self._exitSuccess()
  File "/usr/lib/python2.7/dist-packages/gavo/rsc/data.py", line 161, in _exitSuccess
    feeder.__exit__(None, None, None)
  File "/usr/lib/python2.7/dist-packages/gavo/rsc/dbtable.py", line 105, in __exit__
    table._Feeder.__exit__(self, *args)
  File "/usr/lib/python2.7/dist-packages/gavo/rsc/table.py", line 91, in __exit__
    self.table.importFinished()
  File "/usr/lib/python2.7/dist-packages/gavo/rsc/dbtable.py", line 657, in importFinished
    self.runScripts("postCreation")
  File "/usr/lib/python2.7/dist-packages/gavo/rsc/table.py", line 196, in runScripts
    self._runScripts(self, phase, **kwargs)
  File "/usr/lib/python2.7/dist-packages/gavo/rscdef/scripting.py", line 252, in runScripts
    runner.run(table, **kwargs)
  File "/usr/lib/python2.7/dist-packages/gavo/rscdef/scripting.py", line 178, in run
    func(dbTable, **kwargs)
  File "<string>", line 11, in scriptFun
  File "/usr/lib/python2.7/dist-packages/gavo/rsc/dbtable.py", line 543, in query
    return DBMethodsMixin.query(self, query, data)
  File "/usr/lib/python2.7/dist-packages/gavo/base/sqlsupport.py", line 735, in query
    cursor.execute(query, data)
ProgrammingError: column "accref" does not exist
LINE 36:       CAST(accref AS text) AS obs_id,
                    ^

2014-10-02 10:15:28,302 [ERROR 17471] Uncaught exception at toplevel
Traceback (most recent call last):
  File "/usr/lib/python2.7/dist-packages/gavo/user/cli.py", line 158, in main
    funcToRun()
  File "/usr/lib/python2.7/dist-packages/gavo/user/importing.py", line 153, in main
    sys.exit(process(opts, args))
  File "/usr/lib/python2.7/dist-packages/gavo/user/importing.py", line 79, in process
    rsc.makeDependentsFor(dds, opts, connection)
  File "/usr/lib/python2.7/dist-packages/gavo/rsc/data.py", line 498, in makeDependentsFor
    makeData(dd, parseOptions=parseOptions, connection=connection)
  File "/usr/lib/python2.7/dist-packages/gavo/rsc/data.py", line 451, in makeData
    processSource(res, forceSource, feeder, parseOptions, connection)
  File "/usr/lib/python2.7/dist-packages/gavo/rsc/data.py", line 177, in __exit__
    self._exitSuccess()
  File "/usr/lib/python2.7/dist-packages/gavo/rsc/data.py", line 161, in _exitSuccess
    feeder.__exit__(None, None, None)
  File "/usr/lib/python2.7/dist-packages/gavo/rsc/dbtable.py", line 105, in __exit__
    table._Feeder.__exit__(self, *args)
  File "/usr/lib/python2.7/dist-packages/gavo/rsc/table.py", line 91, in __exit__
    self.table.importFinished()
  File "/usr/lib/python2.7/dist-packages/gavo/rsc/dbtable.py", line 657, in importFinished
    self.runScripts("postCreation")
  File "/usr/lib/python2.7/dist-packages/gavo/rsc/table.py", line 196, in runScripts
    self._runScripts(self, phase, **kwargs)
  File "/usr/lib/python2.7/dist-packages/gavo/rscdef/scripting.py", line 252, in runScripts
    runner.run(table, **kwargs)
  File "/usr/lib/python2.7/dist-packages/gavo/rscdef/scripting.py", line 178, in run
    func(dbTable, **kwargs)
  File "<string>", line 11, in scriptFun
  File "/usr/lib/python2.7/dist-packages/gavo/rsc/dbtable.py", line 543, in query
    return DBMethodsMixin.query(self, query, data)
  File "/usr/lib/python2.7/dist-packages/gavo/base/sqlsupport.py", line 735, in query
    cursor.execute(query, data)
ProgrammingError: column "accref" does not exist
LINE 36:       CAST(accref AS text) AS obs_id,
                    ^

2014-10-02 10:17:39,929 [ERROR 17483] Uncaught exception at toplevel
Traceback (most recent call last):
  File "/usr/lib/python2.7/dist-packages/gavo/user/cli.py", line 158, in main
    funcToRun()
  File "/usr/lib/python2.7/dist-packages/gavo/user/importing.py", line 153, in main
    sys.exit(process(opts, args))
  File "/usr/lib/python2.7/dist-packages/gavo/user/importing.py", line 79, in process
    rsc.makeDependentsFor(dds, opts, connection)
  File "/usr/lib/python2.7/dist-packages/gavo/rsc/data.py", line 498, in makeDependentsFor
    makeData(dd, parseOptions=parseOptions, connection=connection)
  File "/usr/lib/python2.7/dist-packages/gavo/rsc/data.py", line 451, in makeData
    processSource(res, forceSource, feeder, parseOptions, connection)
  File "/usr/lib/python2.7/dist-packages/gavo/rsc/data.py", line 177, in __exit__
    self._exitSuccess()
  File "/usr/lib/python2.7/dist-packages/gavo/rsc/data.py", line 161, in _exitSuccess
    feeder.__exit__(None, None, None)
  File "/usr/lib/python2.7/dist-packages/gavo/rsc/dbtable.py", line 105, in __exit__
    table._Feeder.__exit__(self, *args)
  File "/usr/lib/python2.7/dist-packages/gavo/rsc/table.py", line 91, in __exit__
    self.table.importFinished()
  File "/usr/lib/python2.7/dist-packages/gavo/rsc/dbtable.py", line 657, in importFinished
    self.runScripts("postCreation")
  File "/usr/lib/python2.7/dist-packages/gavo/rsc/table.py", line 196, in runScripts
    self._runScripts(self, phase, **kwargs)
  File "/usr/lib/python2.7/dist-packages/gavo/rscdef/scripting.py", line 252, in runScripts
    runner.run(table, **kwargs)
  File "/usr/lib/python2.7/dist-packages/gavo/rscdef/scripting.py", line 178, in run
    func(dbTable, **kwargs)
  File "<string>", line 11, in scriptFun
  File "/usr/lib/python2.7/dist-packages/gavo/rsc/dbtable.py", line 543, in query
    return DBMethodsMixin.query(self, query, data)
  File "/usr/lib/python2.7/dist-packages/gavo/base/sqlsupport.py", line 735, in query
    cursor.execute(query, data)
ProgrammingError: column "accref" does not exist
LINE 36:       CAST(accref AS text) AS obs_id,
                    ^

2014-10-02 10:19:43,251 [ERROR 17541] Uncaught exception at toplevel
Traceback (most recent call last):
  File "/usr/lib/python2.7/dist-packages/gavo/user/cli.py", line 158, in main
    funcToRun()
  File "/usr/lib/python2.7/dist-packages/gavo/user/importing.py", line 153, in main
    sys.exit(process(opts, args))
  File "/usr/lib/python2.7/dist-packages/gavo/user/importing.py", line 79, in process
    rsc.makeDependentsFor(dds, opts, connection)
  File "/usr/lib/python2.7/dist-packages/gavo/rsc/data.py", line 498, in makeDependentsFor
    makeData(dd, parseOptions=parseOptions, connection=connection)
  File "/usr/lib/python2.7/dist-packages/gavo/rsc/data.py", line 451, in makeData
    processSource(res, forceSource, feeder, parseOptions, connection)
  File "/usr/lib/python2.7/dist-packages/gavo/rsc/data.py", line 177, in __exit__
    self._exitSuccess()
  File "/usr/lib/python2.7/dist-packages/gavo/rsc/data.py", line 161, in _exitSuccess
    feeder.__exit__(None, None, None)
  File "/usr/lib/python2.7/dist-packages/gavo/rsc/dbtable.py", line 105, in __exit__
    table._Feeder.__exit__(self, *args)
  File "/usr/lib/python2.7/dist-packages/gavo/rsc/table.py", line 91, in __exit__
    self.table.importFinished()
  File "/usr/lib/python2.7/dist-packages/gavo/rsc/dbtable.py", line 657, in importFinished
    self.runScripts("postCreation")
  File "/usr/lib/python2.7/dist-packages/gavo/rsc/table.py", line 196, in runScripts
    self._runScripts(self, phase, **kwargs)
  File "/usr/lib/python2.7/dist-packages/gavo/rscdef/scripting.py", line 252, in runScripts
    runner.run(table, **kwargs)
  File "/usr/lib/python2.7/dist-packages/gavo/rscdef/scripting.py", line 178, in run
    func(dbTable, **kwargs)
  File "<string>", line 11, in scriptFun
  File "/usr/lib/python2.7/dist-packages/gavo/rsc/dbtable.py", line 543, in query
    return DBMethodsMixin.query(self, query, data)
  File "/usr/lib/python2.7/dist-packages/gavo/base/sqlsupport.py", line 735, in query
    cursor.execute(query, data)
ProgrammingError: column "accref" does not exist
LINE 36:       CAST(accref AS text) AS obs_id,
                    ^

2014-10-02 10:31:49,891 [ERROR 17617] Uncaught exception at toplevel
Traceback (most recent call last):
  File "/usr/lib/python2.7/dist-packages/gavo/user/cli.py", line 158, in main
    funcToRun()
  File "/usr/lib/python2.7/dist-packages/gavo/user/importing.py", line 153, in main
    sys.exit(process(opts, args))
  File "/usr/lib/python2.7/dist-packages/gavo/user/importing.py", line 79, in process
    rsc.makeDependentsFor(dds, opts, connection)
  File "/usr/lib/python2.7/dist-packages/gavo/rsc/data.py", line 498, in makeDependentsFor
    makeData(dd, parseOptions=parseOptions, connection=connection)
  File "/usr/lib/python2.7/dist-packages/gavo/rsc/data.py", line 451, in makeData
    processSource(res, forceSource, feeder, parseOptions, connection)
  File "/usr/lib/python2.7/dist-packages/gavo/rsc/data.py", line 177, in __exit__
    self._exitSuccess()
  File "/usr/lib/python2.7/dist-packages/gavo/rsc/data.py", line 161, in _exitSuccess
    feeder.__exit__(None, None, None)
  File "/usr/lib/python2.7/dist-packages/gavo/rsc/dbtable.py", line 105, in __exit__
    table._Feeder.__exit__(self, *args)
  File "/usr/lib/python2.7/dist-packages/gavo/rsc/table.py", line 91, in __exit__
    self.table.importFinished()
  File "/usr/lib/python2.7/dist-packages/gavo/rsc/dbtable.py", line 657, in importFinished
    self.runScripts("postCreation")
  File "/usr/lib/python2.7/dist-packages/gavo/rsc/table.py", line 196, in runScripts
    self._runScripts(self, phase, **kwargs)
  File "/usr/lib/python2.7/dist-packages/gavo/rscdef/scripting.py", line 252, in runScripts
    runner.run(table, **kwargs)
  File "/usr/lib/python2.7/dist-packages/gavo/rscdef/scripting.py", line 178, in run
    func(dbTable, **kwargs)
  File "<string>", line 11, in scriptFun
  File "/usr/lib/python2.7/dist-packages/gavo/rsc/dbtable.py", line 543, in query
    return DBMethodsMixin.query(self, query, data)
  File "/usr/lib/python2.7/dist-packages/gavo/base/sqlsupport.py", line 735, in query
    cursor.execute(query, data)
ProgrammingError: column "accref" does not exist
LINE 36:       CAST(accref AS text) AS obs_id,
                    ^

2014-10-02 10:33:04,043 [ERROR 17621] Uncaught exception at toplevel
Traceback (most recent call last):
  File "/usr/lib/python2.7/dist-packages/gavo/user/cli.py", line 158, in main
    funcToRun()
  File "/usr/lib/python2.7/dist-packages/gavo/user/importing.py", line 153, in main
    sys.exit(process(opts, args))
  File "/usr/lib/python2.7/dist-packages/gavo/user/importing.py", line 79, in process
    rsc.makeDependentsFor(dds, opts, connection)
  File "/usr/lib/python2.7/dist-packages/gavo/rsc/data.py", line 498, in makeDependentsFor
    makeData(dd, parseOptions=parseOptions, connection=connection)
  File "/usr/lib/python2.7/dist-packages/gavo/rsc/data.py", line 451, in makeData
    processSource(res, forceSource, feeder, parseOptions, connection)
  File "/usr/lib/python2.7/dist-packages/gavo/rsc/data.py", line 177, in __exit__
    self._exitSuccess()
  File "/usr/lib/python2.7/dist-packages/gavo/rsc/data.py", line 161, in _exitSuccess
    feeder.__exit__(None, None, None)
  File "/usr/lib/python2.7/dist-packages/gavo/rsc/dbtable.py", line 105, in __exit__
    table._Feeder.__exit__(self, *args)
  File "/usr/lib/python2.7/dist-packages/gavo/rsc/table.py", line 91, in __exit__
    self.table.importFinished()
  File "/usr/lib/python2.7/dist-packages/gavo/rsc/dbtable.py", line 657, in importFinished
    self.runScripts("postCreation")
  File "/usr/lib/python2.7/dist-packages/gavo/rsc/table.py", line 196, in runScripts
    self._runScripts(self, phase, **kwargs)
  File "/usr/lib/python2.7/dist-packages/gavo/rscdef/scripting.py", line 252, in runScripts
    runner.run(table, **kwargs)
  File "/usr/lib/python2.7/dist-packages/gavo/rscdef/scripting.py", line 178, in run
    func(dbTable, **kwargs)
  File "<string>", line 11, in scriptFun
  File "/usr/lib/python2.7/dist-packages/gavo/rsc/dbtable.py", line 543, in query
    return DBMethodsMixin.query(self, query, data)
  File "/usr/lib/python2.7/dist-packages/gavo/base/sqlsupport.py", line 735, in query
    cursor.execute(query, data)
ProgrammingError: column "accref" does not exist
LINE 36:       CAST(accref AS text) AS obs_id,
                    ^

2014-10-02 10:35:16,803 [ERROR 17629] Uncaught exception at toplevel
Traceback (most recent call last):
  File "/usr/lib/python2.7/dist-packages/gavo/user/cli.py", line 158, in main
    funcToRun()
  File "/usr/lib/python2.7/dist-packages/gavo/user/importing.py", line 153, in main
    sys.exit(process(opts, args))
  File "/usr/lib/python2.7/dist-packages/gavo/user/importing.py", line 79, in process
    rsc.makeDependentsFor(dds, opts, connection)
  File "/usr/lib/python2.7/dist-packages/gavo/rsc/data.py", line 498, in makeDependentsFor
    makeData(dd, parseOptions=parseOptions, connection=connection)
  File "/usr/lib/python2.7/dist-packages/gavo/rsc/data.py", line 451, in makeData
    processSource(res, forceSource, feeder, parseOptions, connection)
  File "/usr/lib/python2.7/dist-packages/gavo/rsc/data.py", line 177, in __exit__
    self._exitSuccess()
  File "/usr/lib/python2.7/dist-packages/gavo/rsc/data.py", line 161, in _exitSuccess
    feeder.__exit__(None, None, None)
  File "/usr/lib/python2.7/dist-packages/gavo/rsc/dbtable.py", line 105, in __exit__
    table._Feeder.__exit__(self, *args)
  File "/usr/lib/python2.7/dist-packages/gavo/rsc/table.py", line 91, in __exit__
    self.table.importFinished()
  File "/usr/lib/python2.7/dist-packages/gavo/rsc/dbtable.py", line 657, in importFinished
    self.runScripts("postCreation")
  File "/usr/lib/python2.7/dist-packages/gavo/rsc/table.py", line 196, in runScripts
    self._runScripts(self, phase, **kwargs)
  File "/usr/lib/python2.7/dist-packages/gavo/rscdef/scripting.py", line 252, in runScripts
    runner.run(table, **kwargs)
  File "/usr/lib/python2.7/dist-packages/gavo/rscdef/scripting.py", line 178, in run
    func(dbTable, **kwargs)
  File "<string>", line 11, in scriptFun
  File "/usr/lib/python2.7/dist-packages/gavo/rsc/dbtable.py", line 543, in query
    return DBMethodsMixin.query(self, query, data)
  File "/usr/lib/python2.7/dist-packages/gavo/base/sqlsupport.py", line 735, in query
    cursor.execute(query, data)
ProgrammingError: column "accref" does not exist
LINE 36:       CAST(accref AS text) AS obs_id,
                    ^

2014-10-02 10:37:56,534 [ERROR 17636] Uncaught exception at toplevel
Traceback (most recent call last):
  File "/usr/lib/python2.7/dist-packages/gavo/user/cli.py", line 158, in main
    funcToRun()
  File "/usr/lib/python2.7/dist-packages/gavo/user/importing.py", line 153, in main
    sys.exit(process(opts, args))
  File "/usr/lib/python2.7/dist-packages/gavo/user/importing.py", line 79, in process
    rsc.makeDependentsFor(dds, opts, connection)
  File "/usr/lib/python2.7/dist-packages/gavo/rsc/data.py", line 498, in makeDependentsFor
    makeData(dd, parseOptions=parseOptions, connection=connection)
  File "/usr/lib/python2.7/dist-packages/gavo/rsc/data.py", line 451, in makeData
    processSource(res, forceSource, feeder, parseOptions, connection)
  File "/usr/lib/python2.7/dist-packages/gavo/rsc/data.py", line 177, in __exit__
    self._exitSuccess()
  File "/usr/lib/python2.7/dist-packages/gavo/rsc/data.py", line 161, in _exitSuccess
    feeder.__exit__(None, None, None)
  File "/usr/lib/python2.7/dist-packages/gavo/rsc/dbtable.py", line 105, in __exit__
    table._Feeder.__exit__(self, *args)
  File "/usr/lib/python2.7/dist-packages/gavo/rsc/table.py", line 91, in __exit__
    self.table.importFinished()
  File "/usr/lib/python2.7/dist-packages/gavo/rsc/dbtable.py", line 657, in importFinished
    self.runScripts("postCreation")
  File "/usr/lib/python2.7/dist-packages/gavo/rsc/table.py", line 196, in runScripts
    self._runScripts(self, phase, **kwargs)
  File "/usr/lib/python2.7/dist-packages/gavo/rscdef/scripting.py", line 252, in runScripts
    runner.run(table, **kwargs)
  File "/usr/lib/python2.7/dist-packages/gavo/rscdef/scripting.py", line 178, in run
    func(dbTable, **kwargs)
  File "<string>", line 11, in scriptFun
  File "/usr/lib/python2.7/dist-packages/gavo/rsc/dbtable.py", line 543, in query
    return DBMethodsMixin.query(self, query, data)
  File "/usr/lib/python2.7/dist-packages/gavo/base/sqlsupport.py", line 735, in query
    cursor.execute(query, data)
ProgrammingError: column "accref" does not exist
LINE 36:       CAST(accref AS text) AS obs_id,
                    ^

2014-10-02 10:57:17,453 [ERROR 17751] Uncaught exception at toplevel
Traceback (most recent call last):
  File "/usr/lib/python2.7/dist-packages/gavo/user/cli.py", line 158, in main
    funcToRun()
  File "/usr/lib/python2.7/dist-packages/gavo/user/importing.py", line 153, in main
    sys.exit(process(opts, args))
  File "/usr/lib/python2.7/dist-packages/gavo/user/importing.py", line 79, in process
    rsc.makeDependentsFor(dds, opts, connection)
  File "/usr/lib/python2.7/dist-packages/gavo/rsc/data.py", line 498, in makeDependentsFor
    makeData(dd, parseOptions=parseOptions, connection=connection)
  File "/usr/lib/python2.7/dist-packages/gavo/rsc/data.py", line 451, in makeData
    processSource(res, forceSource, feeder, parseOptions, connection)
  File "/usr/lib/python2.7/dist-packages/gavo/rsc/data.py", line 177, in __exit__
    self._exitSuccess()
  File "/usr/lib/python2.7/dist-packages/gavo/rsc/data.py", line 161, in _exitSuccess
    feeder.__exit__(None, None, None)
  File "/usr/lib/python2.7/dist-packages/gavo/rsc/dbtable.py", line 105, in __exit__
    table._Feeder.__exit__(self, *args)
  File "/usr/lib/python2.7/dist-packages/gavo/rsc/table.py", line 91, in __exit__
    self.table.importFinished()
  File "/usr/lib/python2.7/dist-packages/gavo/rsc/dbtable.py", line 657, in importFinished
    self.runScripts("postCreation")
  File "/usr/lib/python2.7/dist-packages/gavo/rsc/table.py", line 196, in runScripts
    self._runScripts(self, phase, **kwargs)
  File "/usr/lib/python2.7/dist-packages/gavo/rscdef/scripting.py", line 252, in runScripts
    runner.run(table, **kwargs)
  File "/usr/lib/python2.7/dist-packages/gavo/rscdef/scripting.py", line 178, in run
    func(dbTable, **kwargs)
  File "<string>", line 11, in scriptFun
  File "/usr/lib/python2.7/dist-packages/gavo/rsc/dbtable.py", line 543, in query
    return DBMethodsMixin.query(self, query, data)
  File "/usr/lib/python2.7/dist-packages/gavo/base/sqlsupport.py", line 735, in query
    cursor.execute(query, data)
ProgrammingError: column "accref" does not exist
LINE 36:       CAST(accref AS text) AS obs_id,
                    ^

2014-10-02 10:57:54,000 [ERROR 17754] Uncaught exception at toplevel
Traceback (most recent call last):
  File "/usr/lib/python2.7/dist-packages/gavo/user/cli.py", line 158, in main
    funcToRun()
  File "/usr/lib/python2.7/dist-packages/gavo/user/importing.py", line 153, in main
    sys.exit(process(opts, args))
  File "/usr/lib/python2.7/dist-packages/gavo/user/importing.py", line 79, in process
    rsc.makeDependentsFor(dds, opts, connection)
  File "/usr/lib/python2.7/dist-packages/gavo/rsc/data.py", line 498, in makeDependentsFor
    makeData(dd, parseOptions=parseOptions, connection=connection)
  File "/usr/lib/python2.7/dist-packages/gavo/rsc/data.py", line 451, in makeData
    processSource(res, forceSource, feeder, parseOptions, connection)
  File "/usr/lib/python2.7/dist-packages/gavo/rsc/data.py", line 177, in __exit__
    self._exitSuccess()
  File "/usr/lib/python2.7/dist-packages/gavo/rsc/data.py", line 161, in _exitSuccess
    feeder.__exit__(None, None, None)
  File "/usr/lib/python2.7/dist-packages/gavo/rsc/dbtable.py", line 105, in __exit__
    table._Feeder.__exit__(self, *args)
  File "/usr/lib/python2.7/dist-packages/gavo/rsc/table.py", line 91, in __exit__
    self.table.importFinished()
  File "/usr/lib/python2.7/dist-packages/gavo/rsc/dbtable.py", line 657, in importFinished
    self.runScripts("postCreation")
  File "/usr/lib/python2.7/dist-packages/gavo/rsc/table.py", line 196, in runScripts
    self._runScripts(self, phase, **kwargs)
  File "/usr/lib/python2.7/dist-packages/gavo/rscdef/scripting.py", line 252, in runScripts
    runner.run(table, **kwargs)
  File "/usr/lib/python2.7/dist-packages/gavo/rscdef/scripting.py", line 178, in run
    func(dbTable, **kwargs)
  File "<string>", line 11, in scriptFun
  File "/usr/lib/python2.7/dist-packages/gavo/rsc/dbtable.py", line 543, in query
    return DBMethodsMixin.query(self, query, data)
  File "/usr/lib/python2.7/dist-packages/gavo/base/sqlsupport.py", line 735, in query
    cursor.execute(query, data)
ProgrammingError: column "accref" does not exist
LINE 36:       CAST(accref AS text) AS obs_id,
                    ^

